Traceback (most recent call last):
  File "/home/daniel/.conda/envs/qce-tut/lib/python3.9/site-packages/jupyter_cache/executors/utils.py", line 51, in single_nb_execution
    executenb(
  File "/home/daniel/.conda/envs/qce-tut/lib/python3.9/site-packages/nbclient/client.py", line 1204, in execute
    return NotebookClient(nb=nb, resources=resources, km=km, **kwargs).execute()
  File "/home/daniel/.conda/envs/qce-tut/lib/python3.9/site-packages/nbclient/util.py", line 84, in wrapped
    return just_run(coro(*args, **kwargs))
  File "/home/daniel/.conda/envs/qce-tut/lib/python3.9/site-packages/nbclient/util.py", line 62, in just_run
    return loop.run_until_complete(coro)
  File "/home/daniel/.conda/envs/qce-tut/lib/python3.9/asyncio/base_events.py", line 647, in run_until_complete
    return future.result()
  File "/home/daniel/.conda/envs/qce-tut/lib/python3.9/site-packages/nbclient/client.py", line 663, in async_execute
    await self.async_execute_cell(
  File "/home/daniel/.conda/envs/qce-tut/lib/python3.9/site-packages/nbclient/client.py", line 965, in async_execute_cell
    await self._check_raise_for_error(cell, cell_index, exec_reply)
  File "/home/daniel/.conda/envs/qce-tut/lib/python3.9/site-packages/nbclient/client.py", line 862, in _check_raise_for_error
    raise CellExecutionError.from_cell_and_msg(cell, exec_reply_content)
nbclient.exceptions.CellExecutionError: An error occurred while executing the following cell:
------------------
import qutip as qp

T = 1
times = np.linspace(0, T, 100)


H = np.array([[1, 1], [1, -1]]) / np.sqrt(2)

H0 = 0 * np.pi * qp.sigmaz()


R = 150
H_ops = [qp.sigmax(), qp.sigmay()]

from qutip.control import cy_grape_unitary
from qutip.ui.progressbar import TextProgressBar

x = np.linspace(-1, +1, times.size)
initial_amplitudes = 1e-3 * np.stack([np.exp(-x**2), np.exp(-x**2)], -1)

qutip_pulse = cy_grape_unitary(qp.Qobj(H), H0, H_ops, R, times,u_start=initial_amplitudes.T, eps=2*np.pi/T, phase_sensitive=False)

plt.plot(initial_amplitudes)
------------------

[0;31m---------------------------------------------------------------------------[0m
[0;31mNameError[0m                                 Traceback (most recent call last)
Cell [0;32mIn [2], line 23[0m
[1;32m     19[0m initial_amplitudes [38;5;241m=[39m [38;5;241m1e-3[39m [38;5;241m*[39m np[38;5;241m.[39mstack([np[38;5;241m.[39mexp([38;5;241m-[39mx[38;5;241m*[39m[38;5;241m*[39m[38;5;241m2[39m), np[38;5;241m.[39mexp([38;5;241m-[39mx[38;5;241m*[39m[38;5;241m*[39m[38;5;241m2[39m)], [38;5;241m-[39m[38;5;241m1[39m)
[1;32m     21[0m qutip_pulse [38;5;241m=[39m cy_grape_unitary(qp[38;5;241m.[39mQobj(H), H0, H_ops, R, times,u_start[38;5;241m=[39minitial_amplitudes[38;5;241m.[39mT, eps[38;5;241m=[39m[38;5;241m2[39m[38;5;241m*[39mnp[38;5;241m.[39mpi[38;5;241m/[39mT, phase_sensitive[38;5;241m=[39m[38;5;28;01mFalse[39;00m)
[0;32m---> 23[0m [43mplt[49m[38;5;241m.[39mplot(initial_amplitudes)

[0;31mNameError[0m: name 'plt' is not defined
NameError: name 'plt' is not defined

